[2024-05-07T15:35:12.909+0000] {local_task_job_runner.py:120} INFO - ::group::Pre task execution logs
[2024-05-07T15:35:12.923+0000] {taskinstance.py:2076} INFO - Dependencies all met for dep_context=non-requeueable deps ti=<TaskInstance: passing_data_with_variable.prev_variable manual__2024-05-07T15:35:10.194425+00:00 [queued]>
[2024-05-07T15:35:12.928+0000] {taskinstance.py:2076} INFO - Dependencies all met for dep_context=requeueable deps ti=<TaskInstance: passing_data_with_variable.prev_variable manual__2024-05-07T15:35:10.194425+00:00 [queued]>
[2024-05-07T15:35:12.929+0000] {taskinstance.py:2306} INFO - Starting attempt 1 of 1
[2024-05-07T15:35:12.936+0000] {taskinstance.py:2330} INFO - Executing <Task(_PythonDecoratedOperator): prev_variable> on 2024-05-07 15:35:10.194425+00:00
[2024-05-07T15:35:12.940+0000] {standard_task_runner.py:63} INFO - Started process 429 to run task
[2024-05-07T15:35:12.942+0000] {standard_task_runner.py:90} INFO - Running: ['***', 'tasks', 'run', 'passing_data_with_variable', 'prev_variable', 'manual__2024-05-07T15:35:10.194425+00:00', '--job-id', '12', '--raw', '--subdir', 'DAGS_FOLDER/passing_data_with_variable.py', '--cfg-path', '/tmp/tmp3krkj7us']
[2024-05-07T15:35:12.944+0000] {standard_task_runner.py:91} INFO - Job 12: Subtask prev_variable
[2024-05-07T15:35:12.974+0000] {task_command.py:426} INFO - Running <TaskInstance: passing_data_with_variable.prev_variable manual__2024-05-07T15:35:10.194425+00:00 [running]> on host d1aba41f8dcb
[2024-05-07T15:35:13.023+0000] {taskinstance.py:2648} INFO - Exporting env vars: AIRFLOW_CTX_DAG_OWNER='***' AIRFLOW_CTX_DAG_ID='passing_data_with_variable' AIRFLOW_CTX_TASK_ID='prev_variable' AIRFLOW_CTX_EXECUTION_DATE='2024-05-07T15:35:10.194425+00:00' AIRFLOW_CTX_TRY_NUMBER='1' AIRFLOW_CTX_DAG_RUN_ID='manual__2024-05-07T15:35:10.194425+00:00'
[2024-05-07T15:35:13.024+0000] {taskinstance.py:430} INFO - ::endgroup::
[2024-05-07T15:35:13.030+0000] {taskinstance.py:441} INFO - ::group::Post task execution logs
[2024-05-07T15:35:13.033+0000] {taskinstance.py:2905} ERROR - Task failed with exception
Traceback (most recent call last):
  File "/home/airflow/.local/lib/python3.11/site-packages/airflow/models/taskinstance.py", line 465, in _execute_task
    result = _execute_callable(context=context, **execute_callable_kwargs)
             ^^^^^^^^^^^^^^^^^^^^^^^^^^^^^^^^^^^^^^^^^^^^^^^^^^^^^^^^^^^^^
  File "/home/airflow/.local/lib/python3.11/site-packages/airflow/models/taskinstance.py", line 432, in _execute_callable
    return execute_callable(context=context, **execute_callable_kwargs)
           ^^^^^^^^^^^^^^^^^^^^^^^^^^^^^^^^^^^^^^^^^^^^^^^^^^^^^^^^^^^^
  File "/home/airflow/.local/lib/python3.11/site-packages/airflow/models/baseoperator.py", line 400, in wrapper
    return func(self, *args, **kwargs)
           ^^^^^^^^^^^^^^^^^^^^^^^^^^^
  File "/home/airflow/.local/lib/python3.11/site-packages/airflow/decorators/base.py", line 265, in execute
    return_value = super().execute(context)
                   ^^^^^^^^^^^^^^^^^^^^^^^^
  File "/home/airflow/.local/lib/python3.11/site-packages/airflow/models/baseoperator.py", line 400, in wrapper
    return func(self, *args, **kwargs)
           ^^^^^^^^^^^^^^^^^^^^^^^^^^^
  File "/home/airflow/.local/lib/python3.11/site-packages/airflow/operators/python.py", line 235, in execute
    return_value = self.execute_callable()
                   ^^^^^^^^^^^^^^^^^^^^^^^
  File "/home/airflow/.local/lib/python3.11/site-packages/airflow/operators/python.py", line 252, in execute_callable
    return self.python_callable(*self.op_args, **self.op_kwargs)
           ^^^^^^^^^^^^^^^^^^^^^^^^^^^^^^^^^^^^^^^^^^^^^^^^^^^^^
  File "/opt/airflow/dags/passing_data_with_variable.py", line 15, in prev_variable
    var = Variable.get("data_variable", deserialize_json=True)
          ^^^^^^^^^^^^^^^^^^^^^^^^^^^^^^^^^^^^^^^^^^^^^^^^^^^^
  File "/home/airflow/.local/lib/python3.11/site-packages/airflow/models/variable.py", line 143, in get
    raise KeyError(f"Variable {key} does not exist")
KeyError: 'Variable data_variable does not exist'
[2024-05-07T15:35:13.040+0000] {taskinstance.py:1206} INFO - Marking task as FAILED. dag_id=passing_data_with_variable, task_id=prev_variable, run_id=manual__2024-05-07T15:35:10.194425+00:00, execution_date=20240507T153510, start_date=20240507T153512, end_date=20240507T153513
[2024-05-07T15:35:13.049+0000] {standard_task_runner.py:110} ERROR - Failed to execute job 12 for task prev_variable ('Variable data_variable does not exist'; 429)
[2024-05-07T15:35:13.081+0000] {local_task_job_runner.py:240} INFO - Task exited with return code 1
[2024-05-07T15:35:13.097+0000] {taskinstance.py:3498} INFO - 0 downstream tasks scheduled from follow-on schedule check
[2024-05-07T15:35:13.099+0000] {local_task_job_runner.py:222} INFO - ::endgroup::
