[2024-05-07T15:39:36.989+0000] {local_task_job_runner.py:120} INFO - ::group::Pre task execution logs
[2024-05-07T15:39:37.007+0000] {taskinstance.py:2076} INFO - Dependencies all met for dep_context=non-requeueable deps ti=<TaskInstance: sensor_file.wait_file manual__2024-05-07T15:39:34.838892+00:00 [queued]>
[2024-05-07T15:39:37.020+0000] {taskinstance.py:2076} INFO - Dependencies all met for dep_context=requeueable deps ti=<TaskInstance: sensor_file.wait_file manual__2024-05-07T15:39:34.838892+00:00 [queued]>
[2024-05-07T15:39:37.022+0000] {taskinstance.py:2306} INFO - Starting attempt 1 of 1
[2024-05-07T15:39:37.034+0000] {taskinstance.py:2330} INFO - Executing <Task(FileSensor): wait_file> on 2024-05-07 15:39:34.838892+00:00
[2024-05-07T15:39:37.043+0000] {standard_task_runner.py:63} INFO - Started process 529 to run task
[2024-05-07T15:39:37.046+0000] {standard_task_runner.py:90} INFO - Running: ['***', 'tasks', 'run', 'sensor_file', 'wait_file', 'manual__2024-05-07T15:39:34.838892+00:00', '--job-id', '27', '--raw', '--subdir', 'DAGS_FOLDER/sensor_file.py', '--cfg-path', '/tmp/tmpqw75fm08']
[2024-05-07T15:39:37.051+0000] {standard_task_runner.py:91} INFO - Job 27: Subtask wait_file
[2024-05-07T15:39:37.090+0000] {task_command.py:426} INFO - Running <TaskInstance: sensor_file.wait_file manual__2024-05-07T15:39:34.838892+00:00 [running]> on host d1aba41f8dcb
[2024-05-07T15:39:37.162+0000] {taskinstance.py:2648} INFO - Exporting env vars: AIRFLOW_CTX_DAG_OWNER='***' AIRFLOW_CTX_DAG_ID='sensor_file' AIRFLOW_CTX_TASK_ID='wait_file' AIRFLOW_CTX_EXECUTION_DATE='2024-05-07T15:39:34.838892+00:00' AIRFLOW_CTX_TRY_NUMBER='1' AIRFLOW_CTX_DAG_RUN_ID='manual__2024-05-07T15:39:34.838892+00:00'
[2024-05-07T15:39:37.164+0000] {taskinstance.py:430} INFO - ::endgroup::
[2024-05-07T15:39:37.164+0000] {baseoperator.py:399} WARNING - FileSensor.execute cannot be called outside TaskInstance!
[2024-05-07T15:39:37.171+0000] {taskinstance.py:441} INFO - ::group::Post task execution logs
[2024-05-07T15:39:37.180+0000] {taskinstance.py:2905} ERROR - Task failed with exception
Traceback (most recent call last):
  File "/home/airflow/.local/lib/python3.11/site-packages/airflow/models/taskinstance.py", line 465, in _execute_task
    result = _execute_callable(context=context, **execute_callable_kwargs)
             ^^^^^^^^^^^^^^^^^^^^^^^^^^^^^^^^^^^^^^^^^^^^^^^^^^^^^^^^^^^^^
  File "/home/airflow/.local/lib/python3.11/site-packages/airflow/models/taskinstance.py", line 432, in _execute_callable
    return execute_callable(context=context, **execute_callable_kwargs)
           ^^^^^^^^^^^^^^^^^^^^^^^^^^^^^^^^^^^^^^^^^^^^^^^^^^^^^^^^^^^^
  File "/home/airflow/.local/lib/python3.11/site-packages/airflow/models/baseoperator.py", line 400, in wrapper
    return func(self, *args, **kwargs)
           ^^^^^^^^^^^^^^^^^^^^^^^^^^^
  File "/home/airflow/.local/lib/python3.11/site-packages/airflow/sensors/filesystem.py", line 99, in execute
    super().execute(context=context)
  File "/home/airflow/.local/lib/python3.11/site-packages/airflow/models/baseoperator.py", line 400, in wrapper
    return func(self, *args, **kwargs)
           ^^^^^^^^^^^^^^^^^^^^^^^^^^^
  File "/home/airflow/.local/lib/python3.11/site-packages/airflow/sensors/base.py", line 264, in execute
    raise e
  File "/home/airflow/.local/lib/python3.11/site-packages/airflow/sensors/base.py", line 246, in execute
    poke_return = self.poke(context)
                  ^^^^^^^^^^^^^^^^^^
  File "/home/airflow/.local/lib/python3.11/site-packages/airflow/sensors/filesystem.py", line 85, in poke
    self.log.info("Poking for file %s", self.path)
                                        ^^^^^^^^^
  File "/usr/local/lib/python3.11/functools.py", line 1001, in __get__
    val = self.func(instance)
          ^^^^^^^^^^^^^^^^^^^
  File "/home/airflow/.local/lib/python3.11/site-packages/airflow/sensors/filesystem.py", line 79, in path
    hook = FSHook(self.fs_conn_id)
           ^^^^^^^^^^^^^^^^^^^^^^^
  File "/home/airflow/.local/lib/python3.11/site-packages/airflow/hooks/filesystem.py", line 64, in __init__
    conn = self.get_connection(fs_conn_id)
           ^^^^^^^^^^^^^^^^^^^^^^^^^^^^^^^
  File "/home/airflow/.local/lib/python3.11/site-packages/airflow/hooks/base.py", line 83, in get_connection
    conn = Connection.get_connection_from_secrets(conn_id)
           ^^^^^^^^^^^^^^^^^^^^^^^^^^^^^^^^^^^^^^^^^^^^^^^
  File "/home/airflow/.local/lib/python3.11/site-packages/airflow/models/connection.py", line 519, in get_connection_from_secrets
    raise AirflowNotFoundException(f"The conn_id `{conn_id}` isn't defined")
airflow.exceptions.AirflowNotFoundException: The conn_id `fs_default` isn't defined
[2024-05-07T15:39:37.184+0000] {taskinstance.py:1206} INFO - Marking task as FAILED. dag_id=sensor_file, task_id=wait_file, run_id=manual__2024-05-07T15:39:34.838892+00:00, execution_date=20240507T153934, start_date=20240507T153937, end_date=20240507T153937
[2024-05-07T15:39:37.230+0000] {standard_task_runner.py:110} ERROR - Failed to execute job 27 for task wait_file (The conn_id `fs_default` isn't defined; 529)
[2024-05-07T15:39:37.285+0000] {local_task_job_runner.py:240} INFO - Task exited with return code 1
[2024-05-07T15:39:37.303+0000] {taskinstance.py:3498} INFO - 0 downstream tasks scheduled from follow-on schedule check
[2024-05-07T15:39:37.305+0000] {local_task_job_runner.py:222} INFO - ::endgroup::
